<?xml version="1.0" encoding="utf-8"?><testsuites name="pytest tests"><testsuite name="pytest" errors="3" failures="2" skipped="0" tests="13" time="86.502" timestamp="2025-10-15T16:12:50.788073+00:00" hostname="9a3e6803dd95"><testcase classname="tests.e2e.test_backup_restore.TestFullBackupRestore" name="test_full_backup_creation" time="6.676" /><testcase classname="tests.e2e.test_backup_restore.TestFullBackupRestore" name="test_full_restore" time="12.732"><error message="failed on teardown with &quot;ExceptionGroup: errors while tearing down &lt;Function test_full_restore&gt; (2 sub-exceptions)&quot;">+ Exception Group Traceback (most recent call last):
  |   File "/usr/local/lib/python3.11/dist-packages/_pytest/runner.py", line 344, in from_call
  |     result: TResult | None = func()
  |                              ^^^^^^
  |   File "/usr/local/lib/python3.11/dist-packages/_pytest/runner.py", line 246, in &lt;lambda&gt;
  |     lambda: runtest_hook(item=item, **kwds), when=when, reraise=reraise
  |             ^^^^^^^^^^^^^^^^^^^^^^^^^^^^^^^
  |   File "/usr/local/lib/python3.11/dist-packages/pluggy/_hooks.py", line 512, in __call__
  |     return self._hookexec(self.name, self._hookimpls.copy(), kwargs, firstresult)
  |            ^^^^^^^^^^^^^^^^^^^^^^^^^^^^^^^^^^^^^^^^^^^^^^^^^^^^^^^^^^^^^^^^^^^^^^
  |   File "/usr/local/lib/python3.11/dist-packages/pluggy/_manager.py", line 120, in _hookexec
  |     return self._inner_hookexec(hook_name, methods, kwargs, firstresult)
  |            ^^^^^^^^^^^^^^^^^^^^^^^^^^^^^^^^^^^^^^^^^^^^^^^^^^^^^^^^^^^^^
  |   File "/usr/local/lib/python3.11/dist-packages/pluggy/_callers.py", line 167, in _multicall
  |     raise exception
  |   File "/usr/local/lib/python3.11/dist-packages/pluggy/_callers.py", line 139, in _multicall
  |     teardown.throw(exception)
  |   File "/usr/local/lib/python3.11/dist-packages/_pytest/logging.py", line 858, in pytest_runtest_teardown
  |     yield
  |   File "/usr/local/lib/python3.11/dist-packages/pluggy/_callers.py", line 139, in _multicall
  |     teardown.throw(exception)
  |   File "/usr/local/lib/python3.11/dist-packages/_pytest/capture.py", line 905, in pytest_runtest_teardown
  |     return (yield)
  |             ^^^^^
  |   File "/usr/local/lib/python3.11/dist-packages/pluggy/_callers.py", line 121, in _multicall
  |     res = hook_impl.function(*args)
  |           ^^^^^^^^^^^^^^^^^^^^^^^^^
  |   File "/usr/local/lib/python3.11/dist-packages/_pytest/runner.py", line 193, in pytest_runtest_teardown
  |     item.session._setupstate.teardown_exact(nextitem)
  |   File "/usr/local/lib/python3.11/dist-packages/_pytest/runner.py", line 557, in teardown_exact
  |     raise exceptions[0]
  | ExceptionGroup: errors while tearing down &lt;Function test_full_restore&gt; (2 sub-exceptions)
  +-+---------------- 1 ----------------
    | Traceback (most recent call last):
    |   File "/usr/local/lib/python3.11/dist-packages/_pytest/runner.py", line 546, in teardown_exact
    |     fin()
    |   File "/usr/local/lib/python3.11/dist-packages/_pytest/fixtures.py", line 1069, in finish
    |     raise exceptions[0]
    |   File "/usr/local/lib/python3.11/dist-packages/_pytest/fixtures.py", line 1058, in finish
    |     fin()
    |   File "/usr/local/lib/python3.11/dist-packages/_pytest/fixtures.py", line 939, in _teardown_yield_fixture
    |     next(it)
    |   File "/app/tests/e2e/conftest.py", line 99, in db_connection
    |     connection.close()
    |   File "/usr/local/lib/python3.11/dist-packages/pymysql/connections.py", line 424, in close
    |     raise err.Error("Already closed")
    | pymysql.err.Error: Already closed
    +---------------- 2 ----------------
    | Traceback (most recent call last):
    |   File "/usr/local/lib/python3.11/dist-packages/_pytest/runner.py", line 546, in teardown_exact
    |     fin()
    |   File "/usr/local/lib/python3.11/dist-packages/_pytest/fixtures.py", line 1069, in finish
    |     raise exceptions[0]
    |   File "/usr/local/lib/python3.11/dist-packages/_pytest/fixtures.py", line 1058, in finish
    |     fin()
    |   File "/usr/local/lib/python3.11/dist-packages/_pytest/fixtures.py", line 939, in _teardown_yield_fixture
    |     next(it)
    |   File "/app/tests/e2e/conftest.py", line 133, in ensure_clean_state
    |     cursor.execute("SET FOREIGN_KEY_CHECKS = 0")
    |   File "/usr/local/lib/python3.11/dist-packages/pymysql/cursors.py", line 153, in execute
    |     result = self._query(query)
    |              ^^^^^^^^^^^^^^^^^^
    |   File "/usr/local/lib/python3.11/dist-packages/pymysql/cursors.py", line 322, in _query
    |     conn.query(q)
    |   File "/usr/local/lib/python3.11/dist-packages/pymysql/connections.py", line 574, in query
    |     self._execute_command(COMMAND.COM_QUERY, sql)
    |   File "/usr/local/lib/python3.11/dist-packages/pymysql/connections.py", line 844, in _execute_command
    |     raise err.InterfaceError(0, "")
    | pymysql.err.InterfaceError: (0, '')
    +------------------------------------</error></testcase><testcase classname="tests.e2e.test_backup_restore.TestIncrementalBackupRestore" name="test_incremental_backup_creation" time="10.773" /><testcase classname="tests.e2e.test_backup_restore.TestIncrementalBackupRestore" name="test_incremental_restore" time="17.085"><error message="failed on teardown with &quot;ExceptionGroup: errors while tearing down &lt;Function test_incremental_restore&gt; (2 sub-exceptions)&quot;">+ Exception Group Traceback (most recent call last):
  |   File "/usr/local/lib/python3.11/dist-packages/_pytest/runner.py", line 344, in from_call
  |     result: TResult | None = func()
  |                              ^^^^^^
  |   File "/usr/local/lib/python3.11/dist-packages/_pytest/runner.py", line 246, in &lt;lambda&gt;
  |     lambda: runtest_hook(item=item, **kwds), when=when, reraise=reraise
  |             ^^^^^^^^^^^^^^^^^^^^^^^^^^^^^^^
  |   File "/usr/local/lib/python3.11/dist-packages/pluggy/_hooks.py", line 512, in __call__
  |     return self._hookexec(self.name, self._hookimpls.copy(), kwargs, firstresult)
  |            ^^^^^^^^^^^^^^^^^^^^^^^^^^^^^^^^^^^^^^^^^^^^^^^^^^^^^^^^^^^^^^^^^^^^^^
  |   File "/usr/local/lib/python3.11/dist-packages/pluggy/_manager.py", line 120, in _hookexec
  |     return self._inner_hookexec(hook_name, methods, kwargs, firstresult)
  |            ^^^^^^^^^^^^^^^^^^^^^^^^^^^^^^^^^^^^^^^^^^^^^^^^^^^^^^^^^^^^^
  |   File "/usr/local/lib/python3.11/dist-packages/pluggy/_callers.py", line 167, in _multicall
  |     raise exception
  |   File "/usr/local/lib/python3.11/dist-packages/pluggy/_callers.py", line 139, in _multicall
  |     teardown.throw(exception)
  |   File "/usr/local/lib/python3.11/dist-packages/_pytest/logging.py", line 858, in pytest_runtest_teardown
  |     yield
  |   File "/usr/local/lib/python3.11/dist-packages/pluggy/_callers.py", line 139, in _multicall
  |     teardown.throw(exception)
  |   File "/usr/local/lib/python3.11/dist-packages/_pytest/capture.py", line 905, in pytest_runtest_teardown
  |     return (yield)
  |             ^^^^^
  |   File "/usr/local/lib/python3.11/dist-packages/pluggy/_callers.py", line 121, in _multicall
  |     res = hook_impl.function(*args)
  |           ^^^^^^^^^^^^^^^^^^^^^^^^^
  |   File "/usr/local/lib/python3.11/dist-packages/_pytest/runner.py", line 193, in pytest_runtest_teardown
  |     item.session._setupstate.teardown_exact(nextitem)
  |   File "/usr/local/lib/python3.11/dist-packages/_pytest/runner.py", line 557, in teardown_exact
  |     raise exceptions[0]
  | ExceptionGroup: errors while tearing down &lt;Function test_incremental_restore&gt; (2 sub-exceptions)
  +-+---------------- 1 ----------------
    | Traceback (most recent call last):
    |   File "/usr/local/lib/python3.11/dist-packages/_pytest/runner.py", line 546, in teardown_exact
    |     fin()
    |   File "/usr/local/lib/python3.11/dist-packages/_pytest/fixtures.py", line 1069, in finish
    |     raise exceptions[0]
    |   File "/usr/local/lib/python3.11/dist-packages/_pytest/fixtures.py", line 1058, in finish
    |     fin()
    |   File "/usr/local/lib/python3.11/dist-packages/_pytest/fixtures.py", line 939, in _teardown_yield_fixture
    |     next(it)
    |   File "/app/tests/e2e/conftest.py", line 99, in db_connection
    |     connection.close()
    |   File "/usr/local/lib/python3.11/dist-packages/pymysql/connections.py", line 424, in close
    |     raise err.Error("Already closed")
    | pymysql.err.Error: Already closed
    +---------------- 2 ----------------
    | Traceback (most recent call last):
    |   File "/usr/local/lib/python3.11/dist-packages/_pytest/runner.py", line 546, in teardown_exact
    |     fin()
    |   File "/usr/local/lib/python3.11/dist-packages/_pytest/fixtures.py", line 1069, in finish
    |     raise exceptions[0]
    |   File "/usr/local/lib/python3.11/dist-packages/_pytest/fixtures.py", line 1058, in finish
    |     fin()
    |   File "/usr/local/lib/python3.11/dist-packages/_pytest/fixtures.py", line 939, in _teardown_yield_fixture
    |     next(it)
    |   File "/app/tests/e2e/conftest.py", line 133, in ensure_clean_state
    |     cursor.execute("SET FOREIGN_KEY_CHECKS = 0")
    |   File "/usr/local/lib/python3.11/dist-packages/pymysql/cursors.py", line 153, in execute
    |     result = self._query(query)
    |              ^^^^^^^^^^^^^^^^^^
    |   File "/usr/local/lib/python3.11/dist-packages/pymysql/cursors.py", line 322, in _query
    |     conn.query(q)
    |   File "/usr/local/lib/python3.11/dist-packages/pymysql/connections.py", line 574, in query
    |     self._execute_command(COMMAND.COM_QUERY, sql)
    |   File "/usr/local/lib/python3.11/dist-packages/pymysql/connections.py", line 844, in _execute_command
    |     raise err.InterfaceError(0, "")
    | pymysql.err.InterfaceError: (0, '')
    +------------------------------------</error></testcase><testcase classname="tests.e2e.test_backup_restore.TestCredentialsValidation" name="test_backup_requires_credentials_file" time="2.326" /><testcase classname="tests.e2e.test_backup_restore.TestCredentialsValidation" name="test_backup_requires_client_dbcalm_section" time="2.304" /><testcase classname="tests.e2e.test_backup_restore.TestRestorePreconditions" name="test_restore_requires_server_stopped" time="6.672" /><testcase classname="tests.e2e.test_backup_restore.TestRestorePreconditions" name="test_restore_requires_empty_data_directory" time="10.625"><error message="failed on teardown with &quot;ExceptionGroup: errors while tearing down &lt;Function test_restore_requires_empty_data_directory&gt; (2 sub-exceptions)&quot;">+ Exception Group Traceback (most recent call last):
  |   File "/usr/local/lib/python3.11/dist-packages/_pytest/runner.py", line 344, in from_call
  |     result: TResult | None = func()
  |                              ^^^^^^
  |   File "/usr/local/lib/python3.11/dist-packages/_pytest/runner.py", line 246, in &lt;lambda&gt;
  |     lambda: runtest_hook(item=item, **kwds), when=when, reraise=reraise
  |             ^^^^^^^^^^^^^^^^^^^^^^^^^^^^^^^
  |   File "/usr/local/lib/python3.11/dist-packages/pluggy/_hooks.py", line 512, in __call__
  |     return self._hookexec(self.name, self._hookimpls.copy(), kwargs, firstresult)
  |            ^^^^^^^^^^^^^^^^^^^^^^^^^^^^^^^^^^^^^^^^^^^^^^^^^^^^^^^^^^^^^^^^^^^^^^
  |   File "/usr/local/lib/python3.11/dist-packages/pluggy/_manager.py", line 120, in _hookexec
  |     return self._inner_hookexec(hook_name, methods, kwargs, firstresult)
  |            ^^^^^^^^^^^^^^^^^^^^^^^^^^^^^^^^^^^^^^^^^^^^^^^^^^^^^^^^^^^^^
  |   File "/usr/local/lib/python3.11/dist-packages/pluggy/_callers.py", line 167, in _multicall
  |     raise exception
  |   File "/usr/local/lib/python3.11/dist-packages/pluggy/_callers.py", line 139, in _multicall
  |     teardown.throw(exception)
  |   File "/usr/local/lib/python3.11/dist-packages/_pytest/logging.py", line 858, in pytest_runtest_teardown
  |     yield
  |   File "/usr/local/lib/python3.11/dist-packages/pluggy/_callers.py", line 139, in _multicall
  |     teardown.throw(exception)
  |   File "/usr/local/lib/python3.11/dist-packages/_pytest/capture.py", line 905, in pytest_runtest_teardown
  |     return (yield)
  |             ^^^^^
  |   File "/usr/local/lib/python3.11/dist-packages/pluggy/_callers.py", line 121, in _multicall
  |     res = hook_impl.function(*args)
  |           ^^^^^^^^^^^^^^^^^^^^^^^^^
  |   File "/usr/local/lib/python3.11/dist-packages/_pytest/runner.py", line 193, in pytest_runtest_teardown
  |     item.session._setupstate.teardown_exact(nextitem)
  |   File "/usr/local/lib/python3.11/dist-packages/_pytest/runner.py", line 557, in teardown_exact
  |     raise exceptions[0]
  | ExceptionGroup: errors while tearing down &lt;Function test_restore_requires_empty_data_directory&gt; (2 sub-exceptions)
  +-+---------------- 1 ----------------
    | Traceback (most recent call last):
    |   File "/usr/local/lib/python3.11/dist-packages/_pytest/runner.py", line 546, in teardown_exact
    |     fin()
    |   File "/usr/local/lib/python3.11/dist-packages/_pytest/fixtures.py", line 1069, in finish
    |     raise exceptions[0]
    |   File "/usr/local/lib/python3.11/dist-packages/_pytest/fixtures.py", line 1058, in finish
    |     fin()
    |   File "/usr/local/lib/python3.11/dist-packages/_pytest/fixtures.py", line 939, in _teardown_yield_fixture
    |     next(it)
    |   File "/app/tests/e2e/conftest.py", line 99, in db_connection
    |     connection.close()
    |   File "/usr/local/lib/python3.11/dist-packages/pymysql/connections.py", line 424, in close
    |     raise err.Error("Already closed")
    | pymysql.err.Error: Already closed
    +---------------- 2 ----------------
    | Traceback (most recent call last):
    |   File "/usr/local/lib/python3.11/dist-packages/_pytest/runner.py", line 546, in teardown_exact
    |     fin()
    |   File "/usr/local/lib/python3.11/dist-packages/_pytest/fixtures.py", line 1069, in finish
    |     raise exceptions[0]
    |   File "/usr/local/lib/python3.11/dist-packages/_pytest/fixtures.py", line 1058, in finish
    |     fin()
    |   File "/usr/local/lib/python3.11/dist-packages/_pytest/fixtures.py", line 939, in _teardown_yield_fixture
    |     next(it)
    |   File "/app/tests/e2e/conftest.py", line 133, in ensure_clean_state
    |     cursor.execute("SET FOREIGN_KEY_CHECKS = 0")
    |   File "/usr/local/lib/python3.11/dist-packages/pymysql/cursors.py", line 153, in execute
    |     result = self._query(query)
    |              ^^^^^^^^^^^^^^^^^^
    |   File "/usr/local/lib/python3.11/dist-packages/pymysql/cursors.py", line 322, in _query
    |     conn.query(q)
    |   File "/usr/local/lib/python3.11/dist-packages/pymysql/connections.py", line 574, in query
    |     self._execute_command(COMMAND.COM_QUERY, sql)
    |   File "/usr/local/lib/python3.11/dist-packages/pymysql/connections.py", line 844, in _execute_command
    |     raise err.InterfaceError(0, "")
    | pymysql.err.InterfaceError: (0, '')
    +------------------------------------</error></testcase><testcase classname="tests.e2e.test_backup_restore.TestBackupListing" name="test_list_backups" time="10.811"><failure message="TypeError: string indices must be integers, not 'str'">test_backup_restore.py:440: in test_list_backups
    backup_ids_in_response = [b["id"] for b in backups if b["id"] in backup_ids]
                             ^^^^^^^^^^^^^^^^^^^^^^^^^^^^^^^^^^^^^^^^^^^^^^^^^^^
test_backup_restore.py:440: in &lt;listcomp&gt;
    backup_ids_in_response = [b["id"] for b in backups if b["id"] in backup_ids]
                                                          ^^^^^^^
E   TypeError: string indices must be integers, not 'str'</failure></testcase><testcase classname="tests.e2e.test_backup_restore.TestBackupListing" name="test_get_backup_details" time="6.443"><failure message="assert 404 == 200&#10; +  where 404 = &lt;Response [404]&gt;.status_code">test_backup_restore.py:464: in test_get_backup_details
    assert response.status_code == HTTP_OK
E   assert 404 == 200
E    +  where 404 = &lt;Response [404]&gt;.status_code</failure></testcase></testsuite></testsuites>